Workbook

Sheet Dashboard
A1: MARKET MACHINE DASHBOARD v4.6 — FINAL CALIBRATED LIVING ENGINE | K1: LIVE PIPE STATUS
A2: Live evidence engine + calibrated hourly timing/seasonality: FRED + CFTC/TFF + TradingView → Signal Engine → Machine score → calendar timing → final read | K2: Pipe | L2: Source | M2: Status | N2: Latest Value | O2: Last Update | P2: Mode | Q2: Notes | R2: Action
K3: DXY / Price Structure | L3: TradingView Webhook | M3: {=IFERROR(INDEX(Live_Inputs!$D$2:$D$20,MATCH($B$4&"|DXY",Live_Inputs!$A$2:$A$20&"|"&Live_Inputs!$B$2:$B$20,0)),"Manual")} -> Bearish | N3: {=IFERROR(INDEX(Live_Inputs!$E$2:$E$20,MATCH($B$4&"|DXY",Live_Inputs!$A$2:$A$20&"|"&Live_Inputs!$B$2:$B$20,0)),"—")} -> Manual | O3: {=IFERROR(INDEX(Live_Inputs!$F$2:$F$20,MATCH($B$4&"|DXY",Live_Inputs!$A$2:$A$20&"|"&Live_Inputs!$B$2:$B$20,0)),"—")} -> Manual | P3: Live / Manual | Q3: Webhook alert updates this row when configured. | R3: TradingView alert → Apps Script
A4: Selected Asset | B4: XAGUSD | K4: Real Yields | L4: FRED DFII10 | M4: =IF(Live_Inputs!$D$3<>"",Live_Inputs!$D$3,"Manual") -> Bearish | N4: =IF(Live_Inputs!$E$3<>"",Live_Inputs!$E$3,"—") -> 2.11 | O4: =IF(Live_Inputs!$F$3<>"",Live_Inputs!$F$3,"—") -> 46180.553 | P4: Auto | Q4: FRED 10-year TIPS real yield. | R4: Run refreshFRED()
K5: Managed Money | L5: CFTC COT | M5: {=IFERROR(INDEX(Live_Inputs!$D$2:$D$20,MATCH($B$4&"|Managed Money",Live_Inputs!$A$2:$A$20&"|"&Live_Inputs!$B$2:$B$20,0)),"Manual")} -> Bullish | N5: {=IFERROR(INDEX(Live_Inputs!$E$2:$E$20,MATCH($B$4&"|Managed Money",Live_Inputs!$A$2:$A$20&"|"&Live_Inputs!$B$2:$B$20,0)),"—")} -> 23926 | O5: {=IFERROR(INDEX(Live_Inputs!$F$2:$F$20,MATCH($B$4&"|Managed Money",Live_Inputs!$A$2:$A$20&"|"&Live_Inputs!$B$2:$B$20,0)),"—")} -> 46175 | P5: Weekly Auto / Manual | Q5: CFTC updates weekly after Friday release. | R5: Run refreshCFTC()
A6: MACHINE SCORE | K6: Open Interest | L6: CFTC / Exchange / Manual | M6: {=IFERROR(INDEX(Live_Inputs!$D$2:$D$20,MATCH($B$4&"|Open Interest",Live_Inputs!$A$2:$A$20&"|"&Live_Inputs!$B$2:$B$20,0)),"Manual")} -> Bullish | N6: {=IFERROR(INDEX(Live_Inputs!$E$2:$E$20,MATCH($B$4&"|Open Interest",Live_Inputs!$A$2:$A$20&"|"&Live_Inputs!$B$2:$B$20,0)),"—")} -> 102809 | O6: {=IFERROR(INDEX(Live_Inputs!$F$2:$F$20,MATCH($B$4&"|Open Interest",Live_Inputs!$A$2:$A$20&"|"&Live_Inputs!$B$2:$B$20,0)),"—")} -> 46175 | P6: Weekly Auto / Manual | Q6: OI from CFTC report or exchange feed. | R6: Run refreshCFTC()
A7: Variable | B7: Status | C7: Weight | D7: Bullish | E7: Bearish | F7: Neutral | G7: Machine Impact | H7: Notes
A8: DXY | B8: {=IFERROR(XLOOKUP($B$4,Signal_Engine!$A:$A,Signal_Engine!$U:$U),"Neutral")} -> Neutral | C8: {=INDEX(Machine_Input!$G$2:$G$51,MATCH($B$4,Machine_Input!$B$2:$B$51,0))} -> 0.3 | D8: =IF($B8="Bullish","✓","") | E8: =IF($B8="Bearish","✓","") | F8: =IF($B8="Neutral","✓","") -> ✓ | G8: Dollar pressure / relief | H8: Auto from Signal_Engine | K8: V4.6 CALIBRATION NOTE
A9: Real Yields | B9: {=IFERROR(XLOOKUP($B$4,Signal_Engine!$A:$A,Signal_Engine!$Q:$Q),"Neutral")} -> Neutral | C9: {=INDEX(Machine_Input!$H$2:$H$51,MATCH($B$4,Machine_Input!$B$2:$B$51,0))} -> 0.3 | D9: =IF($B9="Bullish","✓","") | E9: =IF($B9="Bearish","✓","") | F9: =IF($B9="Neutral","✓","") -> ✓ | G9: Discount-rate pressure | H9: Auto from Signal_Engine | K9: Timing and seasonality layers now use uploaded hourly datasets for XAGUSD, US30, SPX500, NAS100, plus cross-checks from SI, DJI, VIX, GOLD, and NDX.
A10: Managed Money | B10: {=IFERROR(XLOOKUP($B$4,Signal_Engine!$A:$A,Signal_Engine!$R:$R),"Neutral")} -> Bullish | C10: {=INDEX(Machine_Input!$I$2:$I$51,MATCH($B$4,Machine_Input!$B$2:$B$51,0))} -> 0.25 | D10: =IF($B10="Bullish","✓","") -> ✓ | E10: =IF($B10="Bearish","✓","") | F10: =IF($B10="Neutral","✓","") | G10: Institutional positioning | H10: Auto from Signal_Engine | K10: CFTC script now stages asset-coded proxy rows so Signal_Engine can read XAGUSD/US30/SPX500/NAS100 consistently after refreshCFTC().
A11: Open Interest | B11: {=IFERROR(XLOOKUP($B$4,Signal_Engine!$A:$A,Signal_Engine!$T:$T),"Neutral")} -> Neutral | C11: {=INDEX(Machine_Input!$J$2:$J$51,MATCH($B$4,Machine_Input!$B$2:$B$51,0))} -> 0.15 | D11: =IF($B11="Bullish","✓","") | E11: =IF($B11="Bearish","✓","") | F11: =IF($B11="Neutral","✓","") -> ✓ | G11: Participation / conviction | H11: Auto from Signal_Engine | K11: Next calibration step: run refreshFRED(), refreshCFTC(), then verify Signal_Engine rows update and Dashboard timing layer changes with selected asset. | L11: Living machine-ready after scripts are installed and refreshed.
A13: Bullish Count | B13: {=IFERROR(XLOOKUP($B$4,Signal_Engine!$A:$A,Signal_Engine!$V:$V),0)} -> 1 | C13: Bearish Count | D13: {=IFERROR(XLOOKUP($B$4,Signal_Engine!$A:$A,Signal_Engine!$W:$W),0)} -> 0 | E13: Neutral Count | F13: {=IFERROR(XLOOKUP($B$4,Signal_Engine!$A:$A,Signal_Engine!$X:$X),0)} -> 3 | K13: FINAL WEIGHTED MACHINE
A14: Bullish % | B14: {=IFERROR(XLOOKUP($B$4,Signal_Engine!$A:$A,Signal_Engine!$AQ:$AQ),0)} -> 0.064516129 | C14: Bearish % | D14: {=IFERROR(XLOOKUP($B$4,Signal_Engine!$A:$A,Signal_Engine!$AR:$AR),0)} -> 0.064516129 | E14: Neutral % | F14: {=IFERROR(XLOOKUP($B$4,Signal_Engine!$A:$A,Signal_Engine!$AS:$AS),0)} -> 0.87096774 | K14: Bullish Points | L14: {=IFERROR(XLOOKUP($B$4,Signal_Engine!$A:$A,Signal_Engine!$AN:$AN),0)} -> 10 | M14: Bearish Points | N14: {=IFERROR(XLOOKUP($B$4,Signal_Engine!$A:$A,Signal_Engine!$AO:$AO),0)} -> 10
A15: Machine Bias | B15: {=IFERROR(XLOOKUP($B$4,Signal_Engine!$A:$A,Signal_Engine!$AT:$AT),"Neutral / Mixed")} -> Neutral / Mixed | C15: Evidence Text | D15: {=IFERROR(XLOOKUP($B$4,Signal_Engine!$A:$A,Signal_Engine!$AU:$AU),"")} -> Pts → Bull 10 | Bear 10 | Neutral 135 || Commercial -1,768 (-10) | NonComm 2,406 (10) | OI -17,080 (0) | DXY Neutral (0) | RealYield Neutral (0) | E15: Interpretation | F15: {=IF(B15="Strong Bearish","High-conviction bearish machine pressure.",IF(B15="Strong Bullish","High-conviction bullish machine pressure.",IF(B15="Bearish","Bearish machine pressure outweighs bullish evidence.",IF(B15="Bullish","Bullish machine pressure outweighs bearish evidence.",IF(B15="Moderate Bearish","Moderate bearish skew; confirm with structure/timing.",IF(B15="Moderate Bullish","Moderate bullish skew; confirm with structure/timing.","Mixed machine; wait for cleaner alignment."))))))} -> Mixed machine; wait for cleaner alignment. | K15: Neutral Points | L15: {=IFERROR(XLOOKUP($B$4,Signal_Engine!$A:$A,Signal_Engine!$AP:$AP),0)} -> 135 | M15: Conviction | N15: =MAX(L14,N14)/155 -> 0.064516129
K16: Machine Reading | L16: =B15 -> Neutral / Mixed
A17: SEASONAL LAYER | K17: Score Notes | L17: =D15 -> Pts → Bull 10 | Bear 10 | Neutral 135 || Commercial -1,768 (-10) | NonComm 2,406 (10) | OI -17,080 (0) | DXY Neutral (0) | RealYield Neutral (0)
A18: Current Month | B18: Seasonal Bias | C18: Strength | D18: Calendar Note | E18: Conflict / Confirmation | F18: Source | G18: Update Sheet
A19: =TEXT(TODAY(),"mmmm") -> June | B19: {=IFERROR(INDEX(Seasonality!$D$2:$D$200,MATCH(1,(Seasonality!$A$2:$A$200=$B$4)*(Seasonality!$B$2:$B$200=A19),0)),"Neutral")} -> Bearish | C19: {=IFERROR(INDEX(Seasonality!$E$2:$E$200,MATCH(1,(Seasonality!$A$2:$A$200=$B$4)*(Seasonality!$B$2:$B$200=A19),0)),"Weak")} -> Strong | D19: {=IFERROR(INDEX(Seasonality!$F$2:$F$200,MATCH(1,(Seasonality!$A$2:$A$200=$B$4)*(Seasonality!$B$2:$B$200=A19),0)),"Add seasonal stats")} -> Samples 4 | Win 25.0% | Avg range 11.7% | E19: =IF(AND(B19="Bullish",OR($B$15="Bearish",$B$15="Strong Bearish",$B$15="Moderate Bearish")),"Conflict: bullish seasonality vs bearish machine",IF(AND(B19="Bearish",OR($B$15="Bullish",$B$15="Strong Bullish",$B$15="Moderate Bullish")),"Conflict: bearish seasonality vs bullish machine","Aligned / Neutral")) -> Aligned / Neutral | F19: Seasonality | G19: Seasonality
A22: TIMING LAYER
A23: Machine State Used | B23: Weekly High Window | C23: Weekly Low Window | D23: Primary Hour | E23: Timing Note | F23: Confidence | G23: Source | H23: Update Sheet
A24: =IF(OR($B$15="Strong Bearish",$B$15="Bearish",$B$15="Moderate Bearish"),"Bearish",IF(OR($B$15="Strong Bullish",$B$15="Bullish",$B$15="Moderate Bullish"),"Bullish","Neutral")) -> Neutral | B24: {=IFERROR(INDEX(Timing!$C$2:$C$100,MATCH(1,(Timing!$A$2:$A$100=$B$4)*(Timing!$B$2:$B$100=$A24),0)),"To refine")} -> Friday (35.8%) | Sun–Tue high 35.8% | C24: {=IFERROR(INDEX(Timing!$D$2:$D$100,MATCH(1,(Timing!$A$2:$A$100=$B$4)*(Timing!$B$2:$B$100=$A24),0)),"To refine")} -> Sunday (20.7%) | Sun–Tue low 52.5% | D24: {=IFERROR(INDEX(Timing!$E$2:$E$100,MATCH(1,(Timing!$A$2:$A$100=$B$4)*(Timing!$B$2:$B$100=$A24),0)),"To refine")} -> High 09:00 ET (15.1%) / Low 18:00 ET (18.4%) | E24: {=IFERROR(INDEX(Timing!$G$2:$G$100,MATCH(1,(Timing!$A$2:$A$100=$B$4)*(Timing!$B$2:$B$100=$A24),0)),"To refine")} -> Baseline mixed-machine timing. Use as reference only; high-before-low 44.7%. | F24: {=IFERROR(INDEX(Timing!$H$2:$H$100,MATCH(1,(Timing!$A$2:$A$100=$B$4)*(Timing!$B$2:$B$100=$A24),0)),"To refine")} -> High | G24: {=IFERROR(INDEX(Timing!$J$2:$J$100,MATCH(1,(Timing!$A$2:$A$100=$B$4)*(Timing!$B$2:$B$100=$A24),0)),"To refine")} -> Hourly calibration dataset | H24: Timing
A27: STRUCTURE LAYER
A28: Current Price | B28: Key Level | C28: Structure Status | D28: Acceptance | E28: Structure Score | F28: Note | G28: Last Updated | H28: Update Sheet
A29: {=IFERROR(INDEX(Structure!$B$2:$B$100,MATCH($B$4,Structure!$A$2:$A$100,0)),"Manual")} -> Manual | B29: {=IFERROR(INDEX(Structure!$C$2:$C$100,MATCH($B$4,Structure!$A$2:$A$100,0)),"Manual")} -> 68 / manual | C29: {=IFERROR(INDEX(Structure!$D$2:$D$100,MATCH($B$4,Structure!$A$2:$A$100,0)),"Manual")} -> Below key level | D29: {=IFERROR(INDEX(Structure!$E$2:$E$100,MATCH($B$4,Structure!$A$2:$A$100,0)),"Manual")} -> Pending confirmation | E29: {=IFERROR(INDEX(Structure!$F$2:$F$100,MATCH($B$4,Structure!$A$2:$A$100,0)),"Manual")} -> -1 | F29: {=IFERROR(INDEX(Structure!$G$2:$G$100,MATCH($B$4,Structure!$A$2:$A$100,0)),"Manual")} -> Update manually based on weekly close / acceptance | G29: {=IFERROR(INDEX(Structure!$H$2:$H$100,MATCH($B$4,Structure!$A$2:$A$100,0)),"Manual")} -> Manual | H29: Structure
A32: SIGNAL ENGINE SNAPSHOT
A33: Asset | B33: Commercial Δ | C33: Noncommercial Δ | D33: OI Δ | E33: Real Yield Δ | F33: DXY Signal | G33: Machine Bias | H33: Notes | I33: Next Check
A34: =$B$4 -> XAGUSD | B34: {=IFERROR(XLOOKUP($B$4,Signal_Engine!$A:$A,Signal_Engine!$J:$J),0)} -> -1768 | C34: {=IFERROR(XLOOKUP($B$4,Signal_Engine!$A:$A,Signal_Engine!$M:$M),0)} -> 2406 | D34: {=IFERROR(XLOOKUP($B$4,Signal_Engine!$A:$A,Signal_Engine!$G:$G),0)} -> -17080 | E34: {=IFERROR(XLOOKUP($B$4,Signal_Engine!$A:$A,Signal_Engine!$P:$P),0)} -> 0 | F34: {=IFERROR(XLOOKUP($B$4,Signal_Engine!$A:$A,Signal_Engine!$U:$U),"Neutral")} -> Neutral | G34: {=IFERROR(XLOOKUP($B$4,Signal_Engine!$A:$A,Signal_Engine!$AT:$AT),"Neutral / Mixed")} -> Neutral / Mixed | H34: {=IFERROR(XLOOKUP($B$4,Signal_Engine!$A:$A,Signal_Engine!$AU:$AU),"")} -> Pts → Bull 10 | Bear 10 | Neutral 135 || Commercial -1,768 (-10) | NonComm 2,406 (10) | OI -17,080 (0) | DXY Neutral (0) | RealYield Neutral (0) | I34: {=IFERROR(XLOOKUP($B$4,Signal_Engine!$A:$A,Signal_Engine!$AE:$AE),"")} -> 46182.829
A35: ="FINAL READ: "&$B$4&" | Machine: "&B15&" | Bullish "&TEXT(B14,"0%")&" / Bearish "&TEXT(D14,"0%")&" / Neutral "&TEXT(F14,"0%")&" | Evidence: "&D15&" | Seasonality: "&B19&" / "&C19&" | Timing: "&B24&" → "&E24&" | Structure: "&C29&" / "&D29 -> FINAL READ: XAGUSD | Machine: Neutral / Mixed | Bullish 6% / Bearish 6% / Neutral 87% | Evidence: Pts → Bull 10 | Bear 10 | Neutral 135 || Commercial -1,768 (-10) | NonComm 2,406 (10) | OI -17,080 (0) | DXY Neutral (0) | RealYield Neutral (0) | Seasonality: Bearish / Strong | Timing: Friday (35.8%) | Sun–Tue high 35.8% → Baseline mixed-machine timing. Use as reference only; high-before-low 44.7%. | Structure: Below key level / Pending confirmation

Sheet Machine_Input
A1: Date | B1: Asset | C1: DXY Status | D1: Real Yields Status | E1: Managed Money / Positioning | F1: Open Interest | G1: DXY Weight | H1: Real Yield Weight | I1: Managed Money Weight | J1: OI Weight | K1: Bullish Count | L1: Bearish Count | M1: Neutral Count | N1: Final Bullish % | O1: Final Bearish % | P1: Final Neutral % | Q1: Machine Bias | R1: Evidence Text | S1: Interpretation | T1: Data Mode | U1: DXY Live Status | V1: Real Yield Live Status | W1: MM Live Status | X1: OI Live Status | Y1: Live Freshness | Z1: Live Override? | AA1: Notes
A2: {=IFERROR(INDEX(Signal_Engine!$AE:$AE,MATCH($B2,Signal_Engine!$A:$A,0)),NOW())} -> 46182.829 | B2: XAGUSD | C2: {=IFERROR(XLOOKUP($B2,Signal_Engine!$A:$A,Signal_Engine!$U:$U),"Neutral")} -> Neutral | D2: {=IFERROR(XLOOKUP($B2,Signal_Engine!$A:$A,Signal_Engine!$Q:$Q),"Neutral")} -> Neutral | E2: {=IFERROR(XLOOKUP($B2,Signal_Engine!$A:$A,Signal_Engine!$R:$R),"Neutral")} -> Bullish | F2: {=IFERROR(XLOOKUP($B2,Signal_Engine!$A:$A,Signal_Engine!$T:$T),"Neutral")} -> Neutral | G2: 0.3 | H2: 0.3 | I2: 0.25 | J2: 0.15 | K2: {=IFERROR(INDEX(Signal_Engine!$V:$V,MATCH($B2,Signal_Engine!$A:$A,0)),0)} -> 1 | L2: {=IFERROR(INDEX(Signal_Engine!$W:$W,MATCH($B2,Signal_Engine!$A:$A,0)),0)} -> 0 | M2: {=IFERROR(INDEX(Signal_Engine!$X:$X,MATCH($B2,Signal_Engine!$A:$A,0)),0)} -> 3 | N2: {=IFERROR(XLOOKUP($B2,Signal_Engine!$A:$A,Signal_Engine!$AQ:$AQ),0)} -> 0.064516129 | O2: {=IFERROR(XLOOKUP($B2,Signal_Engine!$A:$A,Signal_Engine!$AR:$AR),0)} -> 0.064516129 | P2: {=IFERROR(XLOOKUP($B2,Signal_Engine!$A:$A,Signal_Engine!$AS:$AS),1)} -> 0.87096774 | Q2: {=IFERROR(XLOOKUP($B2,Signal_Engine!$A:$A,Signal_Engine!$AT:$AT),"Neutral / Mixed")} -> Neutral / Mixed | R2: {=IFERROR(XLOOKUP($B2,Signal_Engine!$A:$A,Signal_Engine!$AU:$AU),"")} -> Pts → Bull 10 | Bear 10 | Neutral 135 || Commercial -1,768 (-10) | NonComm 2,406 (10) | OI -17,080 (0) | DXY Neutral (0) | RealYield Neutral (0) | S2: {=IF(Q2="Strong Bearish","High-conviction bearish machine pressure.",IF(Q2="Strong Bullish","High-conviction bullish machine pressure.",IF(Q2="Bearish","Bearish machine pressure outweighs bullish evidence.",IF(Q2="Bullish","Bullish machine pressure outweighs bearish evidence.",IF(Q2="Moderate Bearish","Moderate bearish skew; confirm with structure/timing.",IF(Q2="Moderate Bullish","Moderate bullish skew; confirm with structure/timing.","Mixed machine; wait for cleaner alignment."))))))} -> Mixed machine; wait for cleaner alignment. | T2: =IF(Z2="Yes","Live","Manual") -> Live | U2: {=C2} -> Neutral | V2: {=D2} -> Neutral | W2: {=E2} -> Bullish | X2: {=F2} -> Neutral | Y2: =A2 -> 46182.829 | Z2: Yes | AA2: {=IFERROR(INDEX(Signal_Engine!$AF:$AF,MATCH($B2,Signal_Engine!$A:$A,0)),"Auto-connected to Signal_Engine.")} -> RealYield Δ 0.00 | NonComm Δ 2,406 | Commercial Δ -1,768 | OI Δ -17,080
A3: {=IFERROR(INDEX(Signal_Engine!$AE:$AE,MATCH($B3,Signal_Engine!$A:$A,0)),NOW())} -> 46182.829 | B3: US30 | C3: {=IFERROR(XLOOKUP($B3,Signal_Engine!$A:$A,Signal_Engine!$U:$U),"Neutral")} -> Neutral | D3: {=IFERROR(XLOOKUP($B3,Signal_Engine!$A:$A,Signal_Engine!$Q:$Q),"Neutral")} -> Neutral | E3: {=IFERROR(XLOOKUP($B3,Signal_Engine!$A:$A,Signal_Engine!$R:$R),"Neutral")} -> Bullish | F3: {=IFERROR(XLOOKUP($B3,Signal_Engine!$A:$A,Signal_Engine!$T:$T),"Neutral")} -> Neutral | G3: 0.3 | H3: 0.3 | I3: 0.25 | J3: 0.15 | K3: {=IFERROR(INDEX(Signal_Engine!$V:$V,MATCH($B3,Signal_Engine!$A:$A,0)),0)} -> 1 | L3: {=IFERROR(INDEX(Signal_Engine!$W:$W,MATCH($B3,Signal_Engine!$A:$A,0)),0)} -> 0 | M3: {=IFERROR(INDEX(Signal_Engine!$X:$X,MATCH($B3,Signal_Engine!$A:$A,0)),0)} -> 3 | N3: {=IFERROR(XLOOKUP($B3,Signal_Engine!$A:$A,Signal_Engine!$AQ:$AQ),0)} -> 0.064516129 | O3: {=IFERROR(XLOOKUP($B3,Signal_Engine!$A:$A,Signal_Engine!$AR:$AR),0)} -> 0.064516129 | P3: {=IFERROR(XLOOKUP($B3,Signal_Engine!$A:$A,Signal_Engine!$AS:$AS),1)} -> 0.87096774 | Q3: {=IFERROR(XLOOKUP($B3,Signal_Engine!$A:$A,Signal_Engine!$AT:$AT),"Neutral / Mixed")} -> Neutral / Mixed | R3: {=IFERROR(XLOOKUP($B3,Signal_Engine!$A:$A,Signal_Engine!$AU:$AU),"")} -> Pts → Bull 10 | Bear 10 | Neutral 135 || Commercial -1,198 (-10) | NonComm 1,939 (10) | OI -1,455 (0) | DXY Neutral (0) | RealYield Neutral (0) | S3: {=IF(Q3="Strong Bearish","High-conviction bearish machine pressure.",IF(Q3="Strong Bullish","High-conviction bullish machine pressure.",IF(Q3="Bearish","Bearish machine pressure outweighs bullish evidence.",IF(Q3="Bullish","Bullish machine pressure outweighs bearish evidence.",IF(Q3="Moderate Bearish","Moderate bearish skew; confirm with structure/timing.",IF(Q3="Moderate Bullish","Moderate bullish skew; confirm with structure/timing.","Mixed machine; wait for cleaner alignment."))))))} -> Mixed machine; wait for cleaner alignment. | T3: =IF(Z3="Yes","Live","Manual") -> Live | U3: {=C3} -> Neutral | V3: {=D3} -> Neutral | W3: {=E3} -> Bullish | X3: {=F3} -> Neutral | Y3: =A3 -> 46182.829 | Z3: Yes | AA3: {=IFERROR(INDEX(Signal_Engine!$AF:$AF,MATCH($B3,Signal_Engine!$A:$A,0)),"Auto-connected to Signal_Engine.")} -> RealYield Δ 0.00 | NonComm Δ 1,939 | Commercial Δ -1,198 | OI Δ -1,455
A4: {=IFERROR(INDEX(Signal_Engine!$AE:$AE,MATCH($B4,Signal_Engine!$A:$A,0)),NOW())} -> 46182.829 | B4: SPX500 | C4: {=IFERROR(XLOOKUP($B4,Signal_Engine!$A:$A,Signal_Engine!$U:$U),"Neutral")} -> Neutral | D4: {=IFERROR(XLOOKUP($B4,Signal_Engine!$A:$A,Signal_Engine!$Q:$Q),"Neutral")} -> Neutral | E4: {=IFERROR(XLOOKUP($B4,Signal_Engine!$A:$A,Signal_Engine!$R:$R),"Neutral")} -> Bearish | F4: {=IFERROR(XLOOKUP($B4,Signal_Engine!$A:$A,Signal_Engine!$T:$T),"Neutral")} -> Neutral | G4: 0.3 | H4: 0.3 | I4: 0.25 | J4: 0.15 | K4: {=IFERROR(INDEX(Signal_Engine!$V:$V,MATCH($B4,Signal_Engine!$A:$A,0)),0)} -> 0 | L4: {=IFERROR(INDEX(Signal_Engine!$W:$W,MATCH($B4,Signal_Engine!$A:$A,0)),0)} -> 1 | M4: {=IFERROR(INDEX(Signal_Engine!$X:$X,MATCH($B4,Signal_Engine!$A:$A,0)),0)} -> 3 | N4: {=IFERROR(XLOOKUP($B4,Signal_Engine!$A:$A,Signal_Engine!$AQ:$AQ),0)} -> 0.25806452 | O4: {=IFERROR(XLOOKUP($B4,Signal_Engine!$A:$A,Signal_Engine!$AR:$AR),0)} -> 0.25806452 | P4: {=IFERROR(XLOOKUP($B4,Signal_Engine!$A:$A,Signal_Engine!$AS:$AS),1)} -> 0.48387097 | Q4: {=IFERROR(XLOOKUP($B4,Signal_Engine!$A:$A,Signal_Engine!$AT:$AT),"Neutral / Mixed")} -> Neutral / Mixed | R4: {=IFERROR(XLOOKUP($B4,Signal_Engine!$A:$A,Signal_Engine!$AU:$AU),"")} -> Pts → Bull 40 | Bear 40 | Neutral 75 || Commercial 55,145 (40) | NonComm -54,937 (-40) | OI 55,610 (0) | DXY Neutral (0) | RealYield Neutral (0) | S4: {=IF(Q4="Strong Bearish","High-conviction bearish machine pressure.",IF(Q4="Strong Bullish","High-conviction bullish machine pressure.",IF(Q4="Bearish","Bearish machine pressure outweighs bullish evidence.",IF(Q4="Bullish","Bullish machine pressure outweighs bearish evidence.",IF(Q4="Moderate Bearish","Moderate bearish skew; confirm with structure/timing.",IF(Q4="Moderate Bullish","Moderate bullish skew; confirm with structure/timing.","Mixed machine; wait for cleaner alignment."))))))} -> Mixed machine; wait for cleaner alignment. | T4: =IF(Z4="Yes","Live","Manual") -> Live | U4: {=C4} -> Neutral | V4: {=D4} -> Neutral | W4: {=E4} -> Bearish | X4: {=F4} -> Neutral | Y4: =A4 -> 46182.829 | Z4: Yes | AA4: {=IFERROR(INDEX(Signal_Engine!$AF:$AF,MATCH($B4,Signal_Engine!$A:$A,0)),"Auto-connected to Signal_Engine.")} -> RealYield Δ 0.00 | NonComm Δ -54,937 | Commercial Δ 55,145 | OI Δ 55,610
A5: {=IFERROR(INDEX(Signal_Engine!$AE:$AE,MATCH($B5,Signal_Engine!$A:$A,0)),NOW())} -> 46182.829 | B5: NAS100 | C5: {=IFERROR(XLOOKUP($B5,Signal_Engine!$A:$A,Signal_Engine!$U:$U),"Neutral")} -> Neutral | D5: {=IFERROR(XLOOKUP($B5,Signal_Engine!$A:$A,Signal_Engine!$Q:$Q),"Neutral")} -> Neutral | E5: {=IFERROR(XLOOKUP($B5,Signal_Engine!$A:$A,Signal_Engine!$R:$R),"Neutral")} -> Bearish | F5: {=IFERROR(XLOOKUP($B5,Signal_Engine!$A:$A,Signal_Engine!$T:$T),"Neutral")} -> Neutral | G5: 0.3 | H5: 0.3 | I5: 0.25 | J5: 0.15 | K5: {=IFERROR(INDEX(Signal_Engine!$V:$V,MATCH($B5,Signal_Engine!$A:$A,0)),0)} -> 0 | L5: {=IFERROR(INDEX(Signal_Engine!$W:$W,MATCH($B5,Signal_Engine!$A:$A,0)),0)} -> 1 | M5: {=IFERROR(INDEX(Signal_Engine!$X:$X,MATCH($B5,Signal_Engine!$A:$A,0)),0)} -> 3 | N5: {=IFERROR(XLOOKUP($B5,Signal_Engine!$A:$A,Signal_Engine!$AQ:$AQ),0)} -> 0.25806452 | O5: {=IFERROR(XLOOKUP($B5,Signal_Engine!$A:$A,Signal_Engine!$AR:$AR),0)} -> 0.25806452 | P5: {=IFERROR(XLOOKUP($B5,Signal_Engine!$A:$A,Signal_Engine!$AS:$AS),1)} -> 0.48387097 | Q5: {=IFERROR(XLOOKUP($B5,Signal_Engine!$A:$A,Signal_Engine!$AT:$AT),"Neutral / Mixed")} -> Neutral / Mixed | R5: {=IFERROR(XLOOKUP($B5,Signal_Engine!$A:$A,Signal_Engine!$AU:$AU),"")} -> Pts → Bull 40 | Bear 40 | Neutral 75 || Commercial 15,302 (40) | NonComm -10,803 (-40) | OI 15,220 (0) | DXY Neutral (0) | RealYield Neutral (0) | S5: {=IF(Q5="Strong Bearish","High-conviction bearish machine pressure.",IF(Q5="Strong Bullish","High-conviction bullish machine pressure.",IF(Q5="Bearish","Bearish machine pressure outweighs bullish evidence.",IF(Q5="Bullish","Bullish machine pressure outweighs bearish evidence.",IF(Q5="Moderate Bearish","Moderate bearish skew; confirm with structure/timing.",IF(Q5="Moderate Bullish","Moderate bullish skew; confirm with structure/timing.","Mixed machine; wait for cleaner alignment."))))))} -> Mixed machine; wait for cleaner alignment. | T5: =IF(Z5="Yes","Live","Manual") -> Live | U5: {=C5} -> Neutral | V5: {=D5} -> Neutral | W5: {=E5} -> Bearish | X5: {=F5} -> Neutral | Y5: =A5 -> 46182.829 | Z5: Yes | AA5: {=IFERROR(INDEX(Signal_Engine!$AF:$AF,MATCH($B5,Signal_Engine!$A:$A,0)),"Auto-connected to Signal_Engine.")} -> RealYield Δ 0.00 | NonComm Δ -10,803 | Commercial Δ 15,302 | OI Δ 15,220
A6: {=IFERROR(INDEX(Signal_Engine!$AE:$AE,MATCH($B6,Signal_Engine!$A:$A,0)),NOW())} -> 46182.829 | B6: Custom | C6: {=IFERROR(XLOOKUP($B6,Signal_Engine!$A:$A,Signal_Engine!$U:$U),"Neutral")} -> Neutral | D6: {=IFERROR(XLOOKUP($B6,Signal_Engine!$A:$A,Signal_Engine!$Q:$Q),"Neutral")} -> Neutral | E6: {=IFERROR(XLOOKUP($B6,Signal_Engine!$A:$A,Signal_Engine!$R:$R),"Neutral")} -> Neutral | F6: {=IFERROR(XLOOKUP($B6,Signal_Engine!$A:$A,Signal_Engine!$T:$T),"Neutral")} -> Neutral | G6: 0.3 | H6: 0.3 | I6: 0.25 | J6: 0.15 | K6: {=IFERROR(INDEX(Signal_Engine!$V:$V,MATCH($B6,Signal_Engine!$A:$A,0)),0)} -> 0 | L6: {=IFERROR(INDEX(Signal_Engine!$W:$W,MATCH($B6,Signal_Engine!$A:$A,0)),0)} -> 0 | M6: {=IFERROR(INDEX(Signal_Engine!$X:$X,MATCH($B6,Signal_Engine!$A:$A,0)),0)} -> 4 | N6: {=IFERROR(XLOOKUP($B6,Signal_Engine!$A:$A,Signal_Engine!$AQ:$AQ),0)} -> 0 | O6: {=IFERROR(XLOOKUP($B6,Signal_Engine!$A:$A,Signal_Engine!$AR:$AR),0)} -> 0 | P6: {=IFERROR(XLOOKUP($B6,Signal_Engine!$A:$A,Signal_Engine!$AS:$AS),1)} -> 1 | Q6: {=IFERROR(XLOOKUP($B6,Signal_Engine!$A:$A,Signal_Engine!$AT:$AT),"Neutral / Mixed")} -> Neutral / Mixed | R6: {=IFERROR(XLOOKUP($B6,Signal_Engine!$A:$A,Signal_Engine!$AU:$AU),"")} -> Pts → Bull 0 | Bear 0 | Neutral 155 || Commercial 0 (0) | NonComm 0 (0) | OI 0 (0) | DXY Neutral (0) | RealYield Neutral (0) | S6: {=IF(Q6="Strong Bearish","High-conviction bearish machine pressure.",IF(Q6="Strong Bullish","High-conviction bullish machine pressure.",IF(Q6="Bearish","Bearish machine pressure outweighs bullish evidence.",IF(Q6="Bullish","Bullish machine pressure outweighs bearish evidence.",IF(Q6="Moderate Bearish","Moderate bearish skew; confirm with structure/timing.",IF(Q6="Moderate Bullish","Moderate bullish skew; confirm with structure/timing.","Mixed machine; wait for cleaner alignment."))))))} -> Mixed machine; wait for cleaner alignment. | T6: =IF(Z6="Yes","Live","Manual") -> Live | U6: {=C6} -> Neutral | V6: {=D6} -> Neutral | W6: {=E6} -> Neutral | X6: {=F6} -> Neutral | Y6: =A6 -> 46182.829 | Z6: Yes | AA6: {=IFERROR(INDEX(Signal_Engine!$AF:$AF,MATCH($B6,Signal_Engine!$A:$A,0)),"Auto-connected to Signal_Engine.")} -> RealYield Δ 0.00 | NonComm Δ 0 | Commercial Δ 0 | OI Δ 0
K7: {=IFERROR(INDEX(Signal_Engine!$V:$V,MATCH($B7,Signal_Engine!$A:$A,0)),0)} -> 0 | L7: {=IFERROR(INDEX(Signal_Engine!$W:$W,MATCH($B7,Signal_Engine!$A:$A,0)),0)} -> 0 | M7: {=IFERROR(INDEX(Signal_Engine!$X:$X,MATCH($B7,Signal_Engine!$A:$A,0)),0)} -> 0 | N7: {=IFERROR(INDEX(Signal_Engine!$Y:$Y,MATCH($B7,Signal_Engine!$A:$A,0)),0)} -> 0 | O7: {=IFERROR(INDEX(Signal_Engine!$Z:$Z,MATCH($B7,Signal_Engine!$A:$A,0)),0)} -> 0 | P7: {=IFERROR(INDEX(Signal_Engine!$AA:$AA,MATCH($B7,Signal_Engine!$A:$A,0)),0)} -> 0 | Q7: {=IFERROR(INDEX(Signal_Engine!$AB:$AB,MATCH($B7,Signal_Engine!$A:$A,0)),"Neutral / Mixed")} -> Neutral / Mixed | R7: {=IFERROR(INDEX(Signal_Engine!$AC:$AC,MATCH($B7,Signal_Engine!$A:$A,0)),"0/4 Bullish | 0/4 Bearish | 0/4 Neutral")} -> 0/4 Bullish | 0/4 Bearish | 0/4 Neutral | S7: {=IFERROR(INDEX(Signal_Engine!$AD:$AD,MATCH($B7,Signal_Engine!$A:$A,0)),"Mixed machine; wait for cleaner alignment.")} -> Mixed machine; wait for cleaner alignment.
K8: {=IFERROR(INDEX(Signal_Engine!$V:$V,MATCH($B8,Signal_Engine!$A:$A,0)),0)} -> 0 | L8: {=IFERROR(INDEX(Signal_Engine!$W:$W,MATCH($B8,Signal_Engine!$A:$A,0)),0)} -> 0 | M8: {=IFERROR(INDEX(Signal_Engine!$X:$X,MATCH($B8,Signal_Engine!$A:$A,0)),0)} -> 0 | N8: {=IFERROR(INDEX(Signal_Engine!$Y:$Y,MATCH($B8,Signal_Engine!$A:$A,0)),0)} -> 0 | O8: {=IFERROR(INDEX(Signal_Engine!$Z:$Z,MATCH($B8,Signal_Engine!$A:$A,0)),0)} -> 0 | P8: {=IFERROR(INDEX(Signal_Engine!$AA:$AA,MATCH($B8,Signal_Engine!$A:$A,0)),0)} -> 0 | Q8: {=IFERROR(INDEX(Signal_Engine!$AB:$AB,MATCH($B8,Signal_Engine!$A:$A,0)),"Neutral / Mixed")} -> Neutral / Mixed | R8: {=IFERROR(INDEX(Signal_Engine!$AC:$AC,MATCH($B8,Signal_Engine!$A:$A,0)),"0/4 Bullish | 0/4 Bearish | 0/4 Neutral")} -> 0/4 Bullish | 0/4 Bearish | 0/4 Neutral | S8: {=IFERROR(INDEX(Signal_Engine!$AD:$AD,MATCH($B8,Signal_Engine!$A:$A,0)),"Mixed machine; wait for cleaner alignment.")} -> Mixed machine; wait for cleaner alignment.
K9: {=IFERROR(INDEX(Signal_Engine!$V:$V,MATCH($B9,Signal_Engine!$A:$A,0)),0)} -> 0 | L9: {=IFERROR(INDEX(Signal_Engine!$W:$W,MATCH($B9,Signal_Engine!$A:$A,0)),0)} -> 0 | M9: {=IFERROR(INDEX(Signal_Engine!$X:$X,MATCH($B9,Signal_Engine!$A:$A,0)),0)} -> 0 | N9: {=IFERROR(INDEX(Signal_Engine!$Y:$Y,MATCH($B9,Signal_Engine!$A:$A,0)),0)} -> 0 | O9: {=IFERROR(INDEX(Signal_Engine!$Z:$Z,MATCH($B9,Signal_Engine!$A:$A,0)),0)} -> 0 | P9: {=IFERROR(INDEX(Signal_Engine!$AA:$AA,MATCH($B9,Signal_Engine!$A:$A,0)),0)} -> 0 | Q9: {=IFERROR(INDEX(Signal_Engine!$AB:$AB,MATCH($B9,Signal_Engine!$A:$A,0)),"Neutral / Mixed")} -> Neutral / Mixed | R9: {=IFERROR(INDEX(Signal_Engine!$AC:$AC,MATCH($B9,Signal_Engine!$A:$A,0)),"0/4 Bullish | 0/4 Bearish | 0/4 Neutral")} -> 0/4 Bullish | 0/4 Bearish | 0/4 Neutral | S9: {=IFERROR(INDEX(Signal_Engine!$AD:$AD,MATCH($B9,Signal_Engine!$A:$A,0)),"Mixed machine; wait for cleaner alignment.")} -> Mixed machine; wait for cleaner alignment.
K10: {=IFERROR(INDEX(Signal_Engine!$V:$V,MATCH($B10,Signal_Engine!$A:$A,0)),0)} -> 0 | L10: {=IFERROR(INDEX(Signal_Engine!$W:$W,MATCH($B10,Signal_Engine!$A:$A,0)),0)} -> 0 | M10: {=IFERROR(INDEX(Signal_Engine!$X:$X,MATCH($B10,Signal_Engine!$A:$A,0)),0)} -> 0 | N10: {=IFERROR(INDEX(Signal_Engine!$Y:$Y,MATCH($B10,Signal_Engine!$A:$A,0)),0)} -> 0 | O10: {=IFERROR(INDEX(Signal_Engine!$Z:$Z,MATCH($B10,Signal_Engine!$A:$A,0)),0)} -> 0 | P10: {=IFERROR(INDEX(Signal_Engine!$AA:$AA,MATCH($B10,Signal_Engine!$A:$A,0)),0)} -> 0 | Q10: {=IFERROR(INDEX(Signal_Engine!$AB:$AB,MATCH($B10,Signal_Engine!$A:$A,0)),"Neutral / Mixed")} -> Neutral / Mixed | R10: {=IFERROR(INDEX(Signal_Engine!$AC:$AC,MATCH($B10,Signal_Engine!$A:$A,0)),"0/4 Bullish | 0/4 Bearish | 0/4 Neutral")} -> 0/4 Bullish | 0/4 Bearish | 0/4 Neutral | S10: {=IFERROR(INDEX(Signal_Engine!$AD:$AD,MATCH($B10,Signal_Engine!$A:$A,0)),"Mixed machine; wait for cleaner alignment.")} -> Mixed machine; wait for cleaner alignment.
K11: {=IFERROR(INDEX(Signal_Engine!$V:$V,MATCH($B11,Signal_Engine!$A:$A,0)),0)} -> 0 | L11: {=IFERROR(INDEX(Signal_Engine!$W:$W,MATCH($B11,Signal_Engine!$A:$A,0)),0)} -> 0 | M11: {=IFERROR(INDEX(Signal_Engine!$X:$X,MATCH($B11,Signal_Engine!$A:$A,0)),0)} -> 0 | N11: {=IFERROR(INDEX(Signal_Engine!$Y:$Y,MATCH($B11,Signal_Engine!$A:$A,0)),0)} -> 0 | O11: {=IFERROR(INDEX(Signal_Engine!$Z:$Z,MATCH($B11,Signal_Engine!$A:$A,0)),0)} -> 0 | P11: {=IFERROR(INDEX(Signal_Engine!$AA:$AA,MATCH($B11,Signal_Engine!$A:$A,0)),0)} -> 0 | Q11: {=IFERROR(INDEX(Signal_Engine!$AB:$AB,MATCH($B11,Signal_Engine!$A:$A,0)),"Neutral / Mixed")} -> Neutral / Mixed | R11: {=IFERROR(INDEX(Signal_Engine!$AC:$AC,MATCH($B11,Signal_Engine!$A:$A,0)),"0/4 Bullish | 0/4 Bearish | 0/4 Neutral")} -> 0/4 Bullish | 0/4 Bearish | 0/4 Neutral | S11: {=IFERROR(INDEX(Signal_Engine!$AD:$AD,MATCH($B11,Signal_Engine!$A:$A,0)),"Mixed machine; wait for cleaner alignment.")} -> Mixed machine; wait for cleaner alignment.
K12: {=IFERROR(INDEX(Signal_Engine!$V:$V,MATCH($B12,Signal_Engine!$A:$A,0)),0)} -> 0 | L12: {=IFERROR(INDEX(Signal_Engine!$W:$W,MATCH($B12,Signal_Engine!$A:$A,0)),0)} -> 0 | M12: {=IFERROR(INDEX(Signal_Engine!$X:$X,MATCH($B12,Signal_Engine!$A:$A,0)),0)} -> 0 | N12: {=IFERROR(INDEX(Signal_Engine!$Y:$Y,MATCH($B12,Signal_Engine!$A:$A,0)),0)} -> 0 | O12: {=IFERROR(INDEX(Signal_Engine!$Z:$Z,MATCH($B12,Signal_Engine!$A:$A,0)),0)} -> 0 | P12: {=IFERROR(INDEX(Signal_Engine!$AA:$AA,MATCH($B12,Signal_Engine!$A:$A,0)),0)} -> 0 | Q12: {=IFERROR(INDEX(Signal_Engine!$AB:$AB,MATCH($B12,Signal_Engine!$A:$A,0)),"Neutral / Mixed")} -> Neutral / Mixed | R12: {=IFERROR(INDEX(Signal_Engine!$AC:$AC,MATCH($B12,Signal_Engine!$A:$A,0)),"0/4 Bullish | 0/4 Bearish | 0/4 Neutral")} -> 0/4 Bullish | 0/4 Bearish | 0/4 Neutral | S12: {=IFERROR(INDEX(Signal_Engine!$AD:$AD,MATCH($B12,Signal_Engine!$A:$A,0)),"Mixed machine; wait for cleaner alignment.")} -> Mixed machine; wait for cleaner alignment.
K13: {=IFERROR(INDEX(Signal_Engine!$V:$V,MATCH($B13,Signal_Engine!$A:$A,0)),0)} -> 0 | L13: {=IFERROR(INDEX(Signal_Engine!$W:$W,MATCH($B13,Signal_Engine!$A:$A,0)),0)} -> 0 | M13: {=IFERROR(INDEX(Signal_Engine!$X:$X,MATCH($B13,Signal_Engine!$A:$A,0)),0)} -> 0 | N13: {=IFERROR(INDEX(Signal_Engine!$Y:$Y,MATCH($B13,Signal_Engine!$A:$A,0)),0)} -> 0 | O13: {=IFERROR(INDEX(Signal_Engine!$Z:$Z,MATCH($B13,Signal_Engine!$A:$A,0)),0)} -> 0 | P13: {=IFERROR(INDEX(Signal_Engine!$AA:$AA,MATCH($B13,Signal_Engine!$A:$A,0)),0)} -> 0 | Q13: {=IFERROR(INDEX(Signal_Engine!$AB:$AB,MATCH($B13,Signal_Engine!$A:$A,0)),"Neutral / Mixed")} -> Neutral / Mixed | R13: {=IFERROR(INDEX(Signal_Engine!$AC:$AC,MATCH($B13,Signal_Engine!$A:$A,0)),"0/4 Bullish | 0/4 Bearish | 0/4 Neutral")} -> 0/4 Bullish | 0/4 Bearish | 0/4 Neutral | S13: {=IFERROR(INDEX(Signal_Engine!$AD:$AD,MATCH($B13,Signal_Engine!$A:$A,0)),"Mixed machine; wait for cleaner alignment.")} -> Mixed machine; wait for cleaner alignment.
K14: {=IFERROR(INDEX(Signal_Engine!$V:$V,MATCH($B14,Signal_Engine!$A:$A,0)),0)} -> 0 | L14: {=IFERROR(INDEX(Signal_Engine!$W:$W,MATCH($B14,Signal_Engine!$A:$A,0)),0)} -> 0 | M14: {=IFERROR(INDEX(Signal_Engine!$X:$X,MATCH($B14,Signal_Engine!$A:$A,0)),0)} -> 0 | N14: {=IFERROR(INDEX(Signal_Engine!$Y:$Y,MATCH($B14,Signal_Engine!$A:$A,0)),0)} -> 0 | O14: {=IFERROR(INDEX(Signal_Engine!$Z:$Z,MATCH($B14,Signal_Engine!$A:$A,0)),0)} -> 0 | P14: {=IFERROR(INDEX(Signal_Engine!$AA:$AA,MATCH($B14,Signal_Engine!$A:$A,0)),0)} -> 0 | Q14: {=IFERROR(INDEX(Signal_Engine!$AB:$AB,MATCH($B14,Signal_Engine!$A:$A,0)),"Neutral / Mixed")} -> Neutral / Mixed | R14: {=IFERROR(INDEX(Signal_Engine!$AC:$AC,MATCH($B14,Signal_Engine!$A:$A,0)),"0/4 Bullish | 0/4 Bearish | 0/4 Neutral")} -> 0/4 Bullish | 0/4 Bearish | 0/4 Neutral | S14: {=IFERROR(INDEX(Signal_Engine!$AD:$AD,MATCH($B14,Signal_Engine!$A:$A,0)),"Mixed machine; wait for cleaner alignment.")} -> Mixed machine; wait for cleaner alignment.
K15: {=IFERROR(INDEX(Signal_Engine!$V:$V,MATCH($B15,Signal_Engine!$A:$A,0)),0)} -> 0 | L15: {=IFERROR(INDEX(Signal_Engine!$W:$W,MATCH($B15,Signal_Engine!$A:$A,0)),0)} -> 0 | M15: {=IFERROR(INDEX(Signal_Engine!$X:$X,MATCH($B15,Signal_Engine!$A:$A,0)),0)} -> 0 | N15: {=IFERROR(INDEX(Signal_Engine!$Y:$Y,MATCH($B15,Signal_Engine!$A:$A,0)),0)} -> 0 | O15: {=IFERROR(INDEX(Signal_Engine!$Z:$Z,MATCH($B15,Signal_Engine!$A:$A,0)),0)} -> 0 | P15: {=IFERROR(INDEX(Signal_Engine!$AA:$AA,MATCH($B15,Signal_Engine!$A:$A,0)),0)} -> 0 | Q15: {=IFERROR(INDEX(Signal_Engine!$AB:$AB,MATCH($B15,Signal_Engine!$A:$A,0)),"Neutral / Mixed")} -> Neutral / Mixed | R15: {=IFERROR(INDEX(Signal_Engine!$AC:$AC,MATCH($B15,Signal_Engine!$A:$A,0)),"0/4 Bullish | 0/4 Bearish | 0/4 Neutral")} -> 0/4 Bullish | 0/4 Bearish | 0/4 Neutral | S15: {=IFERROR(INDEX(Signal_Engine!$AD:$AD,MATCH($B15,Signal_Engine!$A:$A,0)),"Mixed machine; wait for cleaner alignment.")} -> Mixed machine; wait for cleaner alignment.
K16: {=IFERROR(INDEX(Signal_Engine!$V:$V,MATCH($B16,Signal_Engine!$A:$A,0)),0)} -> 0 | L16: {=IFERROR(INDEX(Signal_Engine!$W:$W,MATCH($B16,Signal_Engine!$A:$A,0)),0)} -> 0 | M16: {=IFERROR(INDEX(Signal_Engine!$X:$X,MATCH($B16,Signal_Engine!$A:$A,0)),0)} -> 0 | N16: {=IFERROR(INDEX(Signal_Engine!$Y:$Y,MATCH($B16,Signal_Engine!$A:$A,0)),0)} -> 0 | O16: {=IFERROR(INDEX(Signal_Engine!$Z:$Z,MATCH($B16,Signal_Engine!$A:$A,0)),0)} -> 0 | P16: {=IFERROR(INDEX(Signal_Engine!$AA:$AA,MATCH($B16,Signal_Engine!$A:$A,0)),0)} -> 0 | Q16: {=IFERROR(INDEX(Signal_Engine!$AB:$AB,MATCH($B16,Signal_Engine!$A:$A,0)),"Neutral / Mixed")} -> Neutral / Mixed | R16: {=IFERROR(INDEX(Signal_Engine!$AC:$AC,MATCH($B16,Signal_Engine!$A:$A,0)),"0/4 Bullish | 0/4 Bearish | 0/4 Neutral")} -> 0/4 Bullish | 0/4 Bearish | 0/4 Neutral | S16: {=IFERROR(INDEX(Signal_Engine!$AD:$AD,MATCH($B16,Signal_Engine!$A:$A,0)),"Mixed machine; wait for cleaner alignment.")} -> Mixed machine; wait for cleaner alignment.
K17: {=IFERROR(INDEX(Signal_Engine!$V:$V,MATCH($B17,Signal_Engine!$A:$A,0)),0)} -> 0 | L17: {=IFERROR(INDEX(Signal_Engine!$W:$W,MATCH($B17,Signal_Engine!$A:$A,0)),0)} -> 0 | M17: {=IFERROR(INDEX(Signal_Engine!$X:$X,MATCH($B17,Signal_Engine!$A:$A,0)),0)} -> 0 | N17: {=IFERROR(INDEX(Signal_Engine!$Y:$Y,MATCH($B17,Signal_Engine!$A:$A,0)),0)} -> 0 | O17: {=IFERROR(INDEX(Signal_Engine!$Z:$Z,MATCH($B17,Signal_Engine!$A:$A,0)),0)} -> 0 | P17: {=IFERROR(INDEX(Signal_Engine!$AA:$AA,MATCH($B17,Signal_Engine!$A:$A,0)),0)} -> 0 | Q17: {=IFERROR(INDEX(Signal_Engine!$AB:$AB,MATCH($B17,Signal_Engine!$A:$A,0)),"Neutral / Mixed")} -> Neutral / Mixed | R17: {=IFERROR(INDEX(Signal_Engine!$AC:$AC,MATCH($B17,Signal_Engine!$A:$A,0)),"0/4 Bullish | 0/4 Bearish | 0/4 Neutral")} -> 0/4 Bullish | 0/4 Bearish | 0/4 Neutral | S17: {=IFERROR(INDEX(Signal_Engine!$AD:$AD,MATCH($B17,Signal_Engine!$A:$A,0)),"Mixed machine; wait for cleaner alignment.")} -> Mixed machine; wait for cleaner alignment.
K18: {=IFERROR(INDEX(Signal_Engine!$V:$V,MATCH($B18,Signal_Engine!$A:$A,0)),0)} -> 0 | L18: {=IFERROR(INDEX(Signal_Engine!$W:$W,MATCH($B18,Signal_Engine!$A:$A,0)),0)} -> 0 | M18: {=IFERROR(INDEX(Signal_Engine!$X:$X,MATCH($B18,Signal_Engine!$A:$A,0)),0)} -> 0 | N18: {=IFERROR(INDEX(Signal_Engine!$Y:$Y,MATCH($B18,Signal_Engine!$A:$A,0)),0)} -> 0 | O18: {=IFERROR(INDEX(Signal_Engine!$Z:$Z,MATCH($B18,Signal_Engine!$A:$A,0)),0)} -> 0 | P18: {=IFERROR(INDEX(Signal_Engine!$AA:$AA,MATCH($B18,Signal_Engine!$A:$A,0)),0)} -> 0 | Q18: {=IFERROR(INDEX(Signal_Engine!$AB:$AB,MATCH($B18,Signal_Engine!$A:$A,0)),"Neutral / Mixed")} -> Neutral / Mixed | R18: {=IFERROR(INDEX(Signal_Engine!$AC:$AC,MATCH($B18,Signal_Engine!$A:$A,0)),"0/4 Bullish | 0/4 Bearish | 0/4 Neutral")} -> 0/4 Bullish | 0/4 Bearish | 0/4 Neutral | S18: {=IFERROR(INDEX(Signal_Engine!$AD:$AD,MATCH($B18,Signal_Engine!$A:$A,0)),"Mixed machine; wait for cleaner alignment.")} -> Mixed machine; wait for cleaner alignment.
... K51: {=IFERROR(INDEX(Signal_Engine!$V:$V,MATCH($B51,Signal_Engine!$A:$A,0)),0)} -> 0 | L51: {=IFERROR(INDEX(Signal_Engine!$W:$W,MATCH($B51,Signal_Engine!$A:$A,0)),0)} -> 0 | M51: {=IFERROR(INDEX(Signal_Engine!$X:$X,MATCH($B51,Signal_Engine!$A:$A,0)),0)} -> 0 | N51: {=IFERROR(INDEX(Signal_Engine!$Y:$Y,MATCH($B51,Signal_Engine!$A:$A,0)),0)} -> 0 | O51: {=IFERROR(INDEX(Signal_Engine!$Z:$Z,MATCH($B51,Signal_Engine!$A:$A,0)),0)} -> 0 | P51: {=IFERROR(INDEX(Signal_Engine!$AA:$AA,MATCH($B51,Signal_Engine!$A:$A,0)),0)} -> 0 | Q51: {=IFERROR(INDEX(Signal_Engine!$AB:$AB,MATCH($B51,Signal_Engine!$A:$A,0)),"Neutral / Mixed")} -> Neutral / Mixed | R51: {=IFERROR(INDEX(Signal_Engine!$AC:$AC,MATCH($B51,Signal_Engine!$A:$A,0)),"0/4 Bullish | 0/4 Bearish | 0/4 Neutral")} -> 0/4 Bullish | 0/4 Bearish | 0/4 Neutral | S51: {=IFERROR(INDEX(Signal_Engine!$AD:$AD,MATCH($B51,Signal_Engine!$A:$A,0)),"Mixed machine; wait for cleaner alignment.")} -> Mixed machine; wait for cleaner alignment.

Sheet Asset_Config
A1: Asset | B1: Asset Name | C1: Primary Market | D1: Machine Logic | E1: Seasonal Notes | F1: Timing Notes | G1: Default Key Level | H1: Notes | I1: Priority
A2: XAGUSD | B2: Spot Silver | C2: Silver / Precious Metals | D2: DXY + real yields + CFTC silver noncommercial/commercial + OI + calibrated timing. | E2: Seasonality now calibrated from XAGUSD hourly/monthly data; see Seasonality tab. | F2: Bearish: high tends Monday/Sun–Tue; Bullish: low tends Sunday/Sun–Tue; primary decision hour 09:00 ET. | G2: Manual | H2: Uses XAGUSD spot timing + CFTC Silver proxy. SI futures correlation retained in Lead_Lag. | I2: Primary
A3: US30 | B3: Dow Jones / US30 | C3: US equity index | D3: DXY + real yields + TFF/legacy equity positioning proxy + OI + calibrated timing. | E3: Seasonality now calibrated from US30_CFD hourly/monthly data. | F3: Bearish: high tends Monday / low tends Friday; primary hour 09:00 ET. Bullish: low Monday; high Friday. | G3: Manual | H3: Uses US30_CFD timing and TFF/legacy Dow proxy when CFTC pull is available. | I3: Primary
A4: SPX500 | B4: S&P 500 CFD / Index | C4: US equity index | D4: DXY + real yields + TFF S&P proxy + OI + calibrated timing. | E4: Seasonality now calibrated from SPX hourly/monthly data. | F4: Bearish: high Monday / low Friday; bullish: low Monday / high Friday; 09:00 ET dominant. | G4: Manual | H4: Uses SPX timing and CFTC/TFF S&P proxy. Treat as proxy layer for US30 risk. | I4: Optional
A5: NAS100 | B5: Nasdaq / US100 | C5: US growth index | D5: Real yields + DXY + TFF Nasdaq proxy + OI + calibrated timing. | E5: Seasonality now calibrated from NDX hourly/monthly data. | F5: Bearish: high Monday / low Friday; bullish: low Monday / high Friday; 09:00 ET dominant. | G5: Manual | H5: Uses NDX timing and CFTC/TFF Nasdaq proxy; real yields weighted carefully. | I5: Optional
A6: Custom | B6: Custom Instrument | C6: User defined | D6: Define rules manually or import a new asset calibration block. | E6: Define manually | F6: Define manually | G6: Manual | H6: Use dropdowns and manual scoring until calibrated. | I6: Custom

Sheet Seasonality
A1: Asset | B1: Month | C1: Avg Return | D1: Seasonal Bias | E1: Strength | F1: Notes | G1: Rank | H1: Use in Final Read | I1: Source | J1: Last Updated
A2: XAGUSD | B2: January | C2: 0.0548 | D2: Bullish | E2: Strong | F2: Samples 4 | Win 50.0% | Avg range 24.2% | G2: 2 | H2: Yes | I2: Hourly/monthly calibration dataset | J2: 2026-06-09
A3: XAGUSD | B3: February | C3: -0.0045 | D3: Neutral | E3: Weak | F3: Samples 4 | Win 25.0% | Avg range 17.2% | G3: 11 | H3: Optional | I3: Hourly/monthly calibration dataset | J3: 2026-06-09
A4: XAGUSD | B4: March | C4: 0.0352 | D4: Bullish | E4: Strong | F4: Samples 4 | Win 75.0% | Avg range 21.2% | G4: 5 | H4: Yes | I4: Hourly/monthly calibration dataset | J4: 2026-06-09
A5: XAGUSD | B5: April | C5: 0.0065 | D5: Bullish | E5: Moderate | F5: Samples 4 | Win 75.0% | Avg range 16.8% | G5: 10 | H5: Yes | I5: Hourly/monthly calibration dataset | J5: 2026-06-09
A6: XAGUSD | B6: May | C6: 0.0339 | D6: Bullish | E6: Strong | F6: Samples 4 | Win 75.0% | Avg range 17.2% | G6: 6 | H6: Yes | I6: Hourly/monthly calibration dataset | J6: 2026-06-09
A7: XAGUSD | B7: June | C7: -0.0218 | D7: Bearish | E7: Strong | F7: Samples 4 | Win 25.0% | Avg range 11.7% | G7: 12 | H7: Yes | I7: Hourly/monthly calibration dataset | J7: 2026-06-09
A8: XAGUSD | B8: July | C8: 0.0305 | D8: Bullish | E8: Strong | F8: Samples 3 | Win 66.7% | Avg range 12.5% | G8: 9 | H8: Yes | I8: Hourly/monthly calibration dataset | J8: 2026-06-09
A9: XAGUSD | B9: August | C9: 0.0321 | D9: Bullish | E9: Strong | F9: Samples 3 | Win 33.3% | Avg range 12.0% | G9: 8 | H9: Yes | I9: Hourly/monthly calibration dataset | J9: 2026-06-09
A10: XAGUSD | B10: September | C10: 0.0523 | D10: Bullish | E10: Strong | F10: Samples 3 | Win 66.7% | Avg range 15.6% | G10: 3 | H10: Yes | I10: Hourly/monthly calibration dataset | J10: 2026-06-09
A11: XAGUSD | B11: October | C11: 0.0339 | D11: Bullish | E11: Strong | F11: Samples 3 | Win 100.0% | Avg range 15.9% | G11: 7 | H11: Yes | I11: Hourly/monthly calibration dataset | J11: 2026-06-09
A12: XAGUSD | B12: November | C12: 0.075 | D12: Bullish | E12: Strong | F12: Samples 3 | Win 66.7% | Avg range 16.4% | G12: 1 | H12: Yes | I12: Hourly/monthly calibration dataset | J12: 2026-06-09
A13: XAGUSD | B13: December | C13: 0.0468 | D13: Bullish | E13: Strong | F13: Samples 3 | Win 33.3% | Avg range 24.5% | G13: 4 | H13: Yes | I13: Hourly/monthly calibration dataset | J13: 2026-06-09
... A49: NAS100 | B49: December | C49: -0.0053 | D49: Bearish | E49: Moderate | F49: Samples 11 | Win 63.6% | Avg range 7.6% | G49: 11 | H49: Yes | I49: Hourly/monthly calibration dataset | J49: 2026-06-09

Sheet Timing
A1: Asset | B1: Machine State | C1: Weekly High Window | D1: Weekly Low Window | E1: Primary Hour | F1: Secondary Hours | G1: Trap / Continuation Note | H1: Confidence | I1: Sample Size | J1: Source | K1: Last Updated
A2: XAGUSD | B2: Neutral | C2: Friday (35.8%) | Sun–Tue high 35.8% | D2: Sunday (20.7%) | Sun–Tue low 52.5% | E2: High 09:00 ET (15.1%) / Low 18:00 ET (18.4%) | F2: High hrs: 09:00 ET (15.1%), 10:00 ET (8.4%), 13:00 ET (6.7%) | Low hrs: 18:00 ET (18.4%), 09:00 ET (11.2%), 08:00 ET (9.5%) | G2: Baseline mixed-machine timing. Use as reference only; high-before-low 44.7%. | H2: High | I2: 179 weeks | J2: Hourly calibration dataset | K2: 2026-06-09
A3: XAGUSD | B3: Bullish | C3: Friday (62.9%) | Sun–Tue high 10.3% | D3: Sunday (37.1%) | Sun–Tue low 80.4% | E3: High 09:00 ET (15.5%) / Low 18:00 ET (26.8%) | F3: High hrs: 09:00 ET (15.1%), 10:00 ET (8.4%), 13:00 ET (6.7%) | Low hrs: 18:00 ET (18.4%), 09:00 ET (11.2%), 08:00 ET (9.5%) | G3: Bullish template: weekly low tends early; high-before-low only 7.2%. Watch early dip into support then late-week expansion. | H3: Moderate-High | I3: 97 weeks | J3: Hourly calibration dataset | K3: 2026-06-09
A4: XAGUSD | B4: Bearish | C4: Monday (29.3%) | Sun–Tue high 65.9% | D4: Friday (39.0%) | Sun–Tue low 19.5% | E4: High 09:00 ET (14.6%) / Low 09:00 ET (14.6%) | F4: High hrs: 09:00 ET (15.1%), 10:00 ET (8.4%), 13:00 ET (6.7%) | Low hrs: 18:00 ET (18.4%), 09:00 ET (11.2%), 08:00 ET (9.5%) | G4: Bearish template: weekly high tends early; high-before-low 89.0%. Watch early-week rally/fake reclaim into rejection. | H4: Moderate-High | I4: 82 weeks | J4: Hourly calibration dataset | K4: 2026-06-09
A5: XAGUSD | B5: Expansion | C5: Friday (47.1%) | Sun–Tue high 31.8% | D5: Sunday (29.4%) | Sun–Tue low 62.4% | E5: High 09:00 ET (10.6%) / Low 18:00 ET (24.7%) | F5: High hrs: 09:00 ET (15.1%), 10:00 ET (8.4%), 13:00 ET (6.7%) | Low hrs: 18:00 ET (18.4%), 09:00 ET (11.2%), 08:00 ET (9.5%) | G5: Expansion profile: use only after machine aligns and range expands; high-before-low 40.0%. | H5: Moderate-High | I5: 85 weeks | J5: Hourly calibration dataset | K5: 2026-06-09
A6: US30 | B6: Neutral | C6: Friday (35.8%) | Sun–Tue high 34.1% | D6: Friday (26.3%) | Sun–Tue low 44.1% | E6: High 09:00 ET (15.6%) / Low 09:00 ET (14.5%) | F6: High hrs: 09:00 ET (15.6%), 10:00 ET (13.4%), 12:00 ET (11.7%) | Low hrs: 09:00 ET (14.5%), 10:00 ET (11.2%), 15:00 ET (7.8%) | G6: Baseline mixed-machine timing. Use as reference only; high-before-low 43.0%. | H6: High | I6: 179 weeks | J6: Hourly calibration dataset | K6: 2026-06-09
A7: US30 | B7: Bullish | C7: Friday (58.7%) | Sun–Tue high 7.7% | D7: Monday (33.7%) | Sun–Tue low 64.4% | E7: High 10:00 ET (16.3%) / Low 09:00 ET (15.4%) | F7: High hrs: 09:00 ET (15.6%), 10:00 ET (13.4%), 12:00 ET (11.7%) | Low hrs: 09:00 ET (14.5%), 10:00 ET (11.2%), 15:00 ET (7.8%) | G7: Bullish template: weekly low tends early; high-before-low only 12.5%. Watch early dip into support then late-week expansion. | H7: Moderate-High | I7: 104 weeks | J7: Hourly calibration dataset | K7: 2026-06-09
A8: US30 | B8: Bearish | C8: Monday (40.0%) | Sun–Tue high 70.7% | D8: Friday (54.7%) | Sun–Tue low 16.0% | E8: High 09:00 ET (22.7%) / Low 09:00 ET (13.3%) | F8: High hrs: 09:00 ET (15.6%), 10:00 ET (13.4%), 12:00 ET (11.7%) | Low hrs: 09:00 ET (14.5%), 10:00 ET (11.2%), 15:00 ET (7.8%) | G8: Bearish template: weekly high tends early; high-before-low 85.3%. Watch early-week rally/fake reclaim into rejection. | H8: Moderate-High | I8: 75 weeks | J8: Hourly calibration dataset | K8: 2026-06-09
A9: US30 | B9: Expansion | C9: Friday (36.1%) | Sun–Tue high 37.3% | D9: Friday (31.3%) | Sun–Tue low 44.6% | E9: High 12:00 ET (12.0%) / Low 09:00 ET (9.6%) | F9: High hrs: 09:00 ET (15.6%), 10:00 ET (13.4%), 12:00 ET (11.7%) | Low hrs: 09:00 ET (14.5%), 10:00 ET (11.2%), 15:00 ET (7.8%) | G9: Expansion profile: use only after machine aligns and range expands; high-before-low 45.8%. | H9: Moderate-High | I9: 83 weeks | J9: Hourly calibration dataset | K9: 2026-06-09
A10: SPX500 | B10: Neutral | C10: Friday (38.1%) | Sun–Tue high 30.7% | D10: Monday (30.4%) | Sun–Tue low 47.1% | E10: High 09:00 ET (35.6%) / Low 09:00 ET (34.4%) | F10: High hrs: 09:00 ET (35.6%), 15:00 ET (21.6%), 14:00 ET (10.9%) | Low hrs: 09:00 ET (34.4%), 10:00 ET (15.3%), 15:00 ET (14.4%) | G10: Baseline mixed-machine timing. Use as reference only; high-before-low 42.6%. | H10: High | I10: 596 weeks | J10: Hourly calibration dataset | K10: 2026-06-09
A11: SPX500 | B11: Bullish | C11: Friday (61.6%) | Sun–Tue high 6.8% | D11: Monday (49.4%) | Sun–Tue low 71.9% | E11: High 15:00 ET (27.3%) / Low 09:00 ET (44.9%) | F11: High hrs: 09:00 ET (35.6%), 15:00 ET (21.6%), 14:00 ET (10.9%) | Low hrs: 09:00 ET (34.4%), 10:00 ET (15.3%), 15:00 ET (14.4%) | G11: Bullish template: weekly low tends early; high-before-low only 9.7%. Watch early dip into support then late-week expansion. | H11: High | I11: 352 weeks | J11: Hourly calibration dataset | K11: 2026-06-09
A12: SPX500 | B12: Bearish | C12: Monday (38.1%) | Sun–Tue high 65.2% | D12: Friday (53.7%) | Sun–Tue low 11.5% | E12: High 09:00 ET (49.6%) / Low 15:00 ET (22.1%) | F12: High hrs: 09:00 ET (35.6%), 15:00 ET (21.6%), 14:00 ET (10.9%) | Low hrs: 09:00 ET (34.4%), 10:00 ET (15.3%), 15:00 ET (14.4%) | G12: Bearish template: weekly high tends early; high-before-low 90.2%. Watch early-week rally/fake reclaim into rejection. | H12: High | I12: 244 weeks | J12: Hourly calibration dataset | K12: 2026-06-09
... A17: NAS100 | B17: Expansion | C17: Friday (36.8%) | Sun–Tue high 36.4% | D17: Monday (35.4%) | Sun–Tue low 47.8% | E17: High 09:00 ET (40.2%) / Low 09:00 ET (38.8%) | F17: High hrs: 09:00 ET (39.3%), 15:00 ET (20.1%), 10:00 ET (9.9%) | Low hrs: 09:00 ET (39.9%), 10:00 ET (15.1%), 15:00 ET (14.1%) | G17: Expansion profile: use only after machine aligns and range expands; high-before-low 46.4%. | H17: High | I17: 291 weeks | J17: Hourly calibration dataset | K17: 2026-06-09

Sheet Structure
A1: Asset | B1: Current Price | C1: Key Level | D1: Structure Status | E1: Acceptance | F1: Structure Score | G1: Note | H1: Last Updated | I1: Manual Update Sheet
A2: XAGUSD | B2: Manual | C2: 68 / manual | D2: Below key level | E2: Pending confirmation | F2: -1 | G2: Update manually based on weekly close / acceptance | H2: Manual | I2: Structure
A3: US30 | B3: Manual | C3: Manual | D3: At decision zone | E3: Pending confirmation | F3: 0 | G3: Update manually from higher-timeframe structure | H3: Manual | I3: Structure
A4: SPX500 | B4: Manual | C4: Manual | D4: At decision zone | E4: Pending confirmation | F4: 0 | G4: Optional future asset | H4: Manual | I4: Structure
A5: NAS100 | B5: Manual | C5: Manual | D5: At decision zone | E5: Pending confirmation | F5: 0 | G5: Optional future asset | H5: Manual | I5: Structure
A6: Custom | B6: Manual | C6: Manual | D6: At decision zone | E6: Pending confirmation | F6: 0 | G6: User-defined | H6: Manual | I6: Structure

Sheet Data_Log
A1: Date | B1: Asset | C1: Source | D1: Metric | E1: Previous | F1: Current | G1: Change | H1: Direction | I1: Machine Impact | J1: Notes
A2: 46180.22 | B2: XAGUSD | C2: Manual / COT | D2: Managed Money | H2: Bearish | I2: Bearish | J2: Log weekly COT changes here
A3: 46180.22 | B3: XAGUSD | C3: Manual / COT | D3: Open Interest | H3: Bearish | I3: Bearish | J3: Log OI changes here
A4: 46180.22 | B4: XAGUSD | C4: FRED / chart | D4: Real Yields | H4: Bearish | I4: Bearish | J4: Daily or weekly update
A5: 46180.22 | B5: XAGUSD | C5: DXY chart | D5: Dollar Index | H5: Bearish | I5: Bearish | J5: Daily or weekly update

Sheet Lists
A1: Directional Status | B1: Machine Bias | C1: Structure Status | D1: Signal Strength | E1: Assets
A2: Bullish | B2: Strong Bullish | C2: Above key level | D2: Strong | E2: XAGUSD
A3: Neutral | B3: Bullish Bias | C3: Below key level | D3: Moderate | E3: US30
A4: Bearish | B4: Neutral / Mixed | C4: At decision zone | D4: Weak | E4: SPX500
B5: Bearish Bias | C5: Rejecting resistance | D5: Conflict | E5: NAS100
B6: Strong Bearish | C6: Holding support | E6: Custom
C7: Acceptance lower
C8: Acceptance higher

Sheet Instructions
A1: Market Machine v4.6 — Final Calibrated Living Engine
A3: What changed in this version: | D3: Notes | E3: Frequency
A4: 1. Timing layer is populated from uploaded hourly datasets for XAGUSD, US30, SPX500, and NAS100. | D4: XAGUSD, US30, SPX500, NAS100, or Custom | E4: Anytime
A5: 2. Seasonality layer is populated from uploaded monthly/hourly-calibrated data for the same core assets. | D5: Use Bullish / Neutral / Bearish. The dashboard calculates bullish, bearish, and neutral scores automatically. | E5: Daily / Weekly
A6: 3. Calibration support sheets were added: Timing_Calibration, Calendar_Alerts, Lead_Lag, Gap_Behavior, Expansion_Profile, Sequence_Stats, and Calibration_Data_Coverage. | D6: Default: DXY 30%, Real Yields 30%, Managed Money 25%, OI 15%. | E6: As refined
A7: 4. Signal_Engine now uses asset-coded CFTC proxy keys so CFTC_Raw can support XAGUSD, US30, SPX500, and NAS100 after the updated refreshCFTC() script runs. | D7: Current price, key level, acceptance/rejection, decision zone. | E7: Before trading window
A8: 5. AppsScript_Code was upgraded with a dual CFTC pull: Legacy for commodities/legacy series and TFF for financial futures proxies. | D8: Current month flows into Dashboard automatically for selected asset. | E8: Monthly
D9: Bearish and bullish timing profiles can be different. | E9: After data studies
A10: Activation steps: | D10: The machine summarizes evidence; it does not replace discipline. | E10: Every review
A11: A. Upload this workbook to Google Sheets and convert/save as Google Sheets.
A12: B. Extensions → Apps Script → paste AppsScript_Code contents. | D12: No single variable should dominate without context. | E12: Always
A13: C. Run refreshFRED().
A14: D. Run refreshCFTC(). | D14: The sheet is the brain; the app is the face. | E14: Later
A15: E. Return to Dashboard and choose asset from the dropdown.
A17: Interpretation rules:
A18: Machine score is live/weekly and should be read with the Timing layer, not in isolation.
A19: Timing layer is calibrated historical context; it is not a command to enter a trade.
A20: For bearish machine states, early-week high window and Friday low tendencies are prioritized.
A21: For bullish machine states, early-week low window and Friday high tendencies are prioritized.
A23: V4.7 BRIEFING / HEALTH / AI SCAFFOLD
A24: 1 | B24: Use Briefing tab first. It is the front-page market-weather read.
A25: 2 | B25: Use Dashboard for the detailed machine score and drill-down.
A26: 3 | B26: Use Health_Check after refreshAll() to verify feeds are alive.
A27: 4 | B27: Use Alert_Rules as the calendar/notification logic map.
A28: 5 | B28: Use AI_Prompt_Builder for manual AI briefing until API integration is desired.
A29: 6 | B29: AI is optional. The deterministic machine remains the primary source of truth.
A30: 7 | B30: Future app: Streamlit or web app should read Briefing + Dashboard + Signal_Engine.
A31: 8 | B31: Do not store API keys directly in a shared spreadsheet.
A32: 9 | B32: Run refreshFRED daily and refreshCFTC weekly; refreshAll can run both.
A33: 10 | B33: Use Notification_Log as a future output sink for automated email/app/calendar briefings.
A34: 11 | B34: Keep v4.6/v4.7 master archived before making major changes.

Sheet Live_Inputs
A1: Asset | B1: Variable | C1: Source | D1: Status | E1: Latest Value | F1: Last Update | G1: Auto/Manual | H1: Threshold / Rule | I1: Raw Sheet | J1: Notes
A2: XAGUSD | B2: DXY | C2: TradingView webhook / manual | D2: Bearish | E2: Manual | F2: Manual | G2: Manual | H2: DXY rising = Bearish Silver | I2: Webhook_Log | J2: Replace via webhook or manual update.
A3: XAGUSD | B3: Real Yields | C3: FRED DFII10 | D3: Bearish | E3: 2.11 | F3: 46180.553 | G3: Auto | H3: Real yields rising = Bearish Silver | I3: FRED_Raw | J3: refreshFRED() fills FRED_Raw.
A4: XAGUSD | B4: Managed Money | C4: CFTC COT | D4: Bullish | E4: 23926 | F4: 46175 | G4: Weekly Auto / Manual | H4: Managed money liquidating = Bearish Silver | I4: CFTC_Raw | J4: refreshCFTC() fills CFTC_Raw; status can be formula-refined.
A5: XAGUSD | B5: Open Interest | C5: CFTC / exchange | D5: Bullish | E5: 102809 | F5: 46175 | G5: Weekly Auto / Manual | H5: OI contracting with liquidation = Bearish Silver | I5: CFTC_Raw | J5: Use CFTC or exchange OI.
A6: US30 | B6: DXY | C6: TradingView webhook / manual | D6: Neutral | E6: Manual | F6: Manual | G6: Manual | H6: DXY rising often risk-off / Bearish risk assets | I6: Webhook_Log | J6: Replace via webhook or manual update.
A7: US30 | B7: Real Yields | C7: FRED DFII10 | D7: Bearish | E7: 2.11 | F7: 46180.553 | G7: Auto | H7: Real yields rising = pressure on risk assets | I7: FRED_Raw | J7: refreshFRED() fills FRED_Raw.
A8: US30 | B8: Managed Money | C8: CFTC / futures proxy | D8: Neutral | E8: Manual | F8: Manual | G8: Weekly Auto / Manual | H8: Risk positioning deteriorating = Bearish risk assets | I8: CFTC_Raw | J8: Use Dow/YM/TFF when mapped.
A9: US30 | B9: Open Interest | C9: CFTC / exchange | D9: Neutral | E9: Manual | F9: Manual | G9: Weekly Auto / Manual | H9: OI contraction can signal participation loss | I9: CFTC_Raw | J9: Use futures OI if available.
A10: SPX500 | B10: DXY | C10: TradingView webhook / manual | D10: Neutral | E10: Manual | F10: Manual | G10: Manual | H10: DXY rising can pressure risk assets | I10: Webhook_Log | J10: Optional future asset.
A11: NAS100 | B11: Real Yields | C11: FRED DFII10 | D11: Bearish | E11: 2.11 | F11: 46180.553 | G11: Auto | H11: Real yields important for growth assets | I11: FRED_Raw | J11: Optional future asset.

Sheet Source_Map
A1: Data Pipe | B1: Primary Source | C1: URL / Endpoint | D1: Update Frequency | E1: Method | F1: Requires Keys | G1: Feeds Sheet | H1: Notes
A2: Real Yields | B2: FRED DFII10 / DGS10 | C2: https://fred.stlouisfed.org/graph/fredgraph.csv | D2: Daily / on demand | E2: Apps Script refreshFRED() | F2: No | G2: FRED_Raw | H2: Pulls recent real and nominal 10Y yields.
A3: CFTC Legacy | B3: CFTC Legacy Futures Only | C3: https://publicreporting.cftc.gov/resource/6dca-aqww.json | D3: Weekly / after Friday release | E3: Apps Script refreshCFTC() | F3: No | G3: CFTC_Raw | H3: Used for metals and USD Index where commercial/noncommercial reporting is direct.
A4: CFTC TFF | B4: CFTC Traders in Financial Futures | C4: https://publicreporting.cftc.gov/resource/gpe5-46if.json | D4: Weekly / after Friday release | E4: Apps Script refreshCFTC() | F4: No | G4: CFTC_Raw | H4: Used as cleaner financial futures proxy for US30/SPX500/NAS100 where available.
A5: DXY / Structure | B5: TradingView webhook | C5: User-deployed Apps Script Web App URL | D5: Event based | E5: TradingView alert → doPost(e) | F5: TradingView alert access | G5: Webhook_Log / Live_Inputs | H5: Manual fallback remains available.
A6: Timing / Seasonality | B6: Uploaded hourly datasets | C6: Internal calibration sheets | D6: Static until next import | E6: Manual update from data study | F6: No | G6: Timing / Seasonality | H6: This version includes calibration data already.
A8: Briefing Front Page | B8: Internal formulas | C8: Briefing | D8: Every recalculation | E8: Formula | F8: No | G8: Briefing | H8: Compact market-weather output.
A9: Health Check | B9: Internal formulas | C9: Health_Check | D9: Every recalculation | E9: Formula | F9: No | G9: Health_Check | H9: PASS/REVIEW diagnostics.
A10: AI Prompt Builder | B10: Internal formulas | C10: AI_Prompt_Builder | D10: On demand | E10: Formula | F10: No | G10: AI_Prompt_Builder | H10: Copy-paste AI briefing scaffold.
A11: Economic Calendar | B11: Manual / future feed | C11: Economic_Calendar | D11: Manual | E11: Manual/API future | F11: Optional | G11: Economic_Calendar | H11: Event risk/context layer.
A12: Notification Log | B12: Apps Script future | C12: Notification_Log | D12: On trigger | E12: Script | F12: No | G12: Notification_Log | H12: Records sent briefings.
A13: App Roadmap | B13: Internal docs | C13: App_Roadmap | D13: Static | E13: Manual | F13: No | G13: App_Roadmap | H13: Development pathway.
A14: Alert Rules | B14: Internal rules | C14: Alert_Rules | D14: Static | E14: Manual | F14: No | G14: Alert_Rules | H14: Calendar-style alert logic.

Sheet FRED_Raw
A1: Date | B1: DFII10 | C1: DGS10 | D1: Source | E1: Pulled At | F1: Notes

Sheet CFTC_Raw
A1: Report Date | B1: Market | C1: Open Interest | D1: Commercial Long | E1: Commercial Short | F1: Noncommercial Long | G1: Noncommercial Short | H1: Nonreportable Long | I1: Nonreportable Short | J1: Pulled At | K1: Source
A2: 46175 | B2: XAGUSD | C2: 102809 | D2: 25782 | E2: 68443 | F2: 33933 | G2: 10007 | H2: 28097 | I2: 9362 | J2: 46182.829 | K2: legacy | SILVER - COMMODITY EXCHANGE INC.
A3: 46168 | B3: XAGUSD | C3: 18145 | D3: 0 | E3: 0 | F3: 6478 | G3: 7181 | H3: 10231 | I3: 9528 | J3: 46182.829 | K3: legacy | MICRO SILVER - COMMODITY EXCHANGE INC.
A4: 46168 | B4: XAGUSD | C4: 101744 | D4: 27605 | E4: 68498 | F4: 32758 | G4: 10535 | H4: 27301 | I4: 8631 | J4: 46182.829 | K4: legacy | SILVER - COMMODITY EXCHANGE INC.
A5: 46161 | B5: XAGUSD | C5: 100751 | D5: 27108 | E5: 69776 | F5: 34591 | G5: 9920 | H5: 26423 | I5: 8426 | J5: 46182.829 | K5: legacy | SILVER - COMMODITY EXCHANGE INC.
A6: 46154 | B6: XAGUSD | C6: 103800 | D6: 27341 | E6: 70987 | F6: 36569 | G6: 10458 | H6: 27802 | I6: 10267 | J6: 46182.829 | K6: legacy | SILVER - COMMODITY EXCHANGE INC.
A7: 46147 | B7: XAGUSD | C7: 96932 | D7: 26094 | E7: 66629 | F7: 32965 | G7: 9073 | H7: 25811 | I7: 9168 | J7: 46182.829 | K7: legacy | SILVER - COMMODITY EXCHANGE INC.
A8: 46140 | B8: XAGUSD | C8: 101275 | D8: 29676 | E8: 70128 | F8: 31314 | G8: 7154 | H8: 25462 | I8: 9170 | J8: 46182.829 | K8: legacy | SILVER - COMMODITY EXCHANGE INC.
A9: 46133 | B9: XAGUSD | C9: 115462 | D9: 32357 | E9: 73342 | F9: 33233 | G9: 9513 | H9: 26253 | I9: 8988 | J9: 46182.829 | K9: legacy | SILVER - COMMODITY EXCHANGE INC.
A10: 46126 | B10: XAGUSD | C10: 116983 | D10: 32338 | E10: 72471 | F10: 32391 | G10: 8829 | H10: 25765 | I10: 9194 | J10: 46182.829 | K10: legacy | SILVER - COMMODITY EXCHANGE INC.
A11: 46119 | B11: XAGUSD | C11: 115138 | D11: 28211 | E11: 67126 | F11: 32810 | G11: 9393 | H11: 24908 | I11: 9410 | J11: 46182.829 | K11: legacy | SILVER - COMMODITY EXCHANGE INC.
A12: 46112 | B12: XAGUSD | C12: 115169 | D12: 29892 | E12: 68749 | F12: 33463 | G12: 9559 | H12: 24465 | I12: 9512 | J12: 46182.829 | K12: legacy | SILVER - COMMODITY EXCHANGE INC.
